Workbook

Sheet Rapport
A1: RAPPORT — Kalkylakuten
A2: Ren med varningar
A3: Filen är tekniskt stabil och fullt användbar. Men flera strukturella och logiska avvikelser gör att siffrorna kan vara missvisande.
A5: Originalfil: demofil.xlsx
A6: Behandlad: 2026-10-19 09:20
A7: Ändrade celler: 30611 — varav 60 bör granskas i fliken Ändringslogg
A8: Flaggade problem: 44 — se fliken Granska dessa
A10: VAD SOM ÅTGÄRDADES
A11: • 200 textvärden konverterades till tal
A12: • 40 felceller (#DIV/0! m.fl.) rensades
A13: • 40 celler återskapades från kolumnens formelmönster
A14: • 20 döda referenser (#REF!) plockades bort ur formler
... A30: • Filen har fått flikarna "Rapport", "Granska dessa" och "Ändringslogg" — sammanfattningen, flaggade problem och hela ändringsloggen

Sheet Sammanfattning
A2: Nyckeltal 1 | E2: =SUM(B2:D2) | F2: =SUM(B2:E2)
A3: Nyckeltal 2 | B3: =Berakning!C3*B2 | C3: =Berakning!C3*C2 | D3: =Berakning!C3*D2 | E3: =SUM(B3:D3) | F3: =SUM(B3:E3)
A4: Nyckeltal 3 | B4: =Berakning!C4*B2 | C4: =Berakning!C4*C2 | D4: =Berakning!C4*D2 | E4: =SUM(B4:D4) | F4: =SUM(B4:E4)
A5: Nyckeltal 4 | B5: =Berakning!C5*B2 | C5: =Berakning!C5*C2 | D5: =Berakning!C5*D2 | E5: =SUM(B5:D5) | F5: =SUM(B5:E5)
A6: Nyckeltal 5 | B6: =Berakning!C6*B2 | C6: =Berakning!C6*C2 | D6: =Berakning!C6*D2 | E6: =SUM(B6:D6) | F6: =SUM(B6:E6)
A7: Nyckeltal 6 | B7: =Berakning!C7*B2 | C7: =Berakning!C7*C2 | D7: =Berakning!C7*D2 | E7: =SUM(B7:D7) | F7: =SUM(B7:E7)
A8: Nyckeltal 7 | B8: =Berakning!C8*B2 | C8: =Berakning!C8*C2 | D8: =Berakning!C8*D2 | E8: =SUM(B8:D8) | F8: =SUM(B8:E8)
A9: Nyckeltal 8 | B9: =Berakning!C9*B2 | C9: =Berakning!C9*C2 | D9: =Berakning!C9*D2 | E9: =SUM(B9:D9) | F9: =SUM(B9:E9)
A10: Nyckeltal 9 | B10: =Berakning!C10*B2 | C10: =Berakning!C10*C2 | D10: =Berakning!C10*D2 | E10: =SUM(B10:D10) | F10: =SUM(B10:E10)
A11: Nyckeltal 10 | B11: =Berakning!C11*B2 | C11: =Berakning!C11*C2 | D11: =Berakning!C11*D2 | E11: =SUM(B11:D11) | F11: =SUM(B11:E11)
A12: Nyckeltal 11 | B12: =Berakning!C12*B2 | C12: =Berakning!C12*C2 | D12: =Berakning!C12*D2 | E12: =SUM(B12:D12) | F12: =SUM(B12:E12)
A13: Nyckeltal 12 | B13: =Berakning!C13*B2 | C13: =Berakning!C13*C2 | D13: =Berakning!C13*D2 | E13: =SUM(B13:D13) | F13: =SUM(B13:E13)
A14: Nyckeltal 13 | B14: =Berakning!C14*B2 | C14: =Berakning!C14*C2 | D14: =Berakning!C14*D2 | E14: =SUM(B14:D14) | F14: =SUM(B14:E14)
A15: Nyckeltal 14 | B15: =Berakning!C15*B2 | C15: =Berakning!C15*C2 | D15: =Berakning!C15*D2 | E15: =SUM(B15:D15) | F15: =SUM(B15:E15)
A16: Nyckeltal 15 | B16: =Berakning!C16*B2 | C16: =Berakning!C16*C2 | D16: =Berakning!C16*D2 | E16: =SUM(B16:D16) | F16: =SUM(B16:E16)
A17: Nyckeltal 16 | B17: =Berakning!C17*B2 | C17: =Berakning!C17*C2 | D17: =Berakning!C17*D2 | E17: =SUM(B17:D17) | F17: =SUM(B17:E17)
A18: Nyckeltal 17 | B18: =Berakning!C18*B2 | C18: =Berakning!C18*C2 | D18: =Berakning!C18*D2 | E18: =SUM(B18:D18) | F18: =SUM(B18:E18)
A19: Nyckeltal 18 | B19: =Berakning!C19*B2 | C19: =Berakning!C19*C2 | D19: =Berakning!C19*D2 | E19: =SUM(B19:D19) | F19: =SUM(B19:E19)
A20: Nyckeltal 19 | B20: =Berakning!C20*B2 | C20: =Berakning!C20*C2 | D20: =Berakning!C20*D2 | E20: =SUM(B20:D20) | F20: =SUM(B20:E20)
A21: Nyckeltal 20 | B21: =Berakning!C21*B2 | C21: =Berakning!C21*C2 | D21: =Berakning!C21*D2 | E21: =SUM(B21:D21) | F21: =SUM(B21:E21)
A22: Nyckeltal 21 | B22: =Berakning!C22*B2 | C22: =Berakning!C22*C2 | D22: =Berakning!C22*D2 | E22: =SUM(B22:D22) | F22: =SUM(B22:E22)
A23: Nyckeltal 22 | B23: =Berakning!C23*B2 | C23: =Berakning!C23*C2 | D23: =Berakning!C23*D2 | E23: =SUM(B23:D23) | F23: =SUM(B23:E23)
A24: Nyckeltal 23 | B24: =Berakning!C24*B2 | C24: =Berakning!C24*C2 | D24: =Berakning!C24*D2 | E24: =SUM(B24:D24) | F24: =SUM(B24:E24)
A25: Nyckeltal 24 | B25: =Berakning!C25*B2 | C25: =Berakning!C25*C2 | D25: =Berakning!C25*D2 | E25: =SUM(B25:D25) | F25: =SUM(B25:E25)
A26: Nyckeltal 25 | B26: =Berakning!C26*B2 | C26: =Berakning!C26*C2 | D26: =Berakning!C26*D2 | E26: =SUM(B26:D26) | F26: =SUM(B26:E26)
A27: Nyckeltal 26 | B27: =Berakning!C27*B2 | C27: =Berakning!C27*C2 | D27: =Berakning!C27*D2 | E27: =SUM(B27:D27) | F27: =SUM(B27:E27)
A28: Nyckeltal 27 | B28: =Berakning!C28*B2 | C28: =Berakning!C28*C2 | D28: =Berakning!C28*D2 | E28: =SUM(B28:D28) | F28: =SUM(B28:E28)
A29: Nyckeltal 28 | B29: =Berakning!C29*B2 | C29: =Berakning!C29*C2 | D29: =Berakning!C29*D2 | E29: =SUM(B29:D29) | F29: =SUM(B29:E29)
A30: Nyckeltal 29 | B30: =Berakning!C30*B2 | C30: =Berakning!C30*C2 | D30: =Berakning!C30*D2 | E30: =SUM(B30:D30) | F30: =SUM(B30:E30)
A31: Nyckeltal 30 | B31: =Berakning!C31*B2 | C31: =Berakning!C31*C2 | D31: =Berakning!C31*D2 | E31: =SUM(B31:D31) | F31: =SUM(B31:E31)
A32: Nyckeltal 31 | B32: =Berakning!C32*B2 | C32: =Berakning!C32*C2 | D32: =Berakning!C32*D2 | E32: =SUM(B32:D32) | F32: =SUM(B32:E32)
A33: Nyckeltal 32 | B33: =Berakning!C33*B2 | C33: =Berakning!C33*C2 | D33: =Berakning!C33*D2 | E33: =SUM(B33:D33) | F33: =SUM(B33:E33)
A34: Nyckeltal 33 | B34: =Berakning!C34*B2 | C34: =Berakning!C34*C2 | D34: =Berakning!C34*D2 | E34: =SUM(B34:D34) | F34: =SUM(B34:E34)
A35: Nyckeltal 34 | B35: =Berakning!C35*B2 | C35: =Berakning!C35*C2 | D35: =Berakning!C35*D2 | E35: =SUM(B35:D35) | F35: =SUM(B35:E35)
A36: Nyckeltal 35 | B36: =Berakning!C36*B2 | C36: =Berakning!C36*C2 | D36: =Berakning!C36*D2 | E36: =SUM(B36:D36) | F36: =SUM(B36:E36)
A37: Nyckeltal 36 | B37: =Berakning!C37*B2 | C37: =Berakning!C37*C2 | D37: =Berakning!C37*D2 | E37: =SUM(B37:D37) | F37: =SUM(B37:E37)
A38: Nyckeltal 37 | B38: =Berakning!C38*B2 | C38: =Berakning!C38*C2 | D38: =Berakning!C38*D2 | E38: =SUM(B38:D38) | F38: =SUM(B38:E38)
A39: Nyckeltal 38 | B39: =Berakning!C39*B2 | C39: =Berakning!C39*C2 | D39: =Berakning!C39*D2 | E39: =SUM(B39:D39) | F39: =SUM(B39:E39)
A40: Nyckeltal 39 | B40: =Berakning!C40*B2 | C40: =Berakning!C40*C2 | D40: =Berakning!C40*D2 | E40: =SUM(B40:D40) | F40: =SUM(B40:E40)
A41: Nyckeltal 40 | B41: =Berakning!C41*B2 | C41: =Berakning!C41*C2 | D41: =Berakning!C41*D2 | E41: =SUM(B41:D41) | F41: =SUM(B41:E41)
...

Sheet Data
A1: Post | B1: Jan | C1: Feb | D1: Mar | E1: Totalt | F1: Moms | G1: Netto | H1: Marginal | I1: Ack | J1: Kommentar
A2: Konsult 0 | B2: -18361 | C2: 28598 | D2: -1976 | E2: =SUM(B2:D2) | F2: =E2*0.25 | G2: =E2-F2 | H2: =IF(B2>0,G2/B2,0) | I2: =SUM($E$2:E2)
A3: Kontor 1 | B3: -5372 | C3: -10856 | D3: 28265 | E3: =SUM(B3:D3) | F3: =E3*0.25 | G3: =E3-F3 | H3: =IF(B3>0,G3/B3,0) | I3: =SUM($E$2:E3)
A4: Konsult 2 | B4: 24348 | C4: 28540 | D4: 38469 | E4: =SUM(B4:D4) | F4: =E4*0.25 | G4: =E4-F4 | H4: =IF(B4>0,G4/B4,0) | I4: =SUM($E$2:E4)
A5: Frakt 3 | B5: -14303 | C5: 18698 | D5: 7651 | E5: =SUM(B5:D5) | F5: =E5*0.25 | G5: =E5-F5 | H5: =IF(B5>0,G5/B5,0) | I5: =SUM($E$2:E5)
A6: Forsaljning 4 | B6: -18048 | C6: -13860 | D6: -5672 | E6: =SUM(B6:D6) | F6: =E6*0.25 | G6: =E6-F6 | H6: =IF(B6>0,G6/B6,0) | I6: =SUM($E$2:E6)
A7: Kontor 5 | B7: 13118 | C7: 19453 | D7: -18261 | E7: =SUM(B7:D7) | F7: =E7*0.25 | G7: =E7-F7 | H7: =IF(B7>0,G7/B7,0) | I7: =SUM($E$2:E7)
A8: Frakt 6 | B8: -6969 | C8: 26925 | D8: 22590 | E8: =SUM(B8:D8) | F8: =E8*0.25 | G8: =E8-F8 | H8: =IF(B8>0,G8/B8,0) | I8: =SUM($E$2:E8)
A9: Frakt 7 | B9: 7493 | C9: -5554 | D9: 9439 | E9: =SUM(B9:D9) | F9: =E9*0.25 | G9: =E9-F9 | H9: =IF(B9>0,G9/B9,0) | I9: =SUM($E$2:E9)
A10: Ovrigt 8 | B10: -1769 | C10: 33046 | D10: 36970 | E10: =SUM(B10:D10) | F10: =E10*0.25 | G10: =E10-F10 | H10: =IF(B10>0,G10/B10,0) | I10: =SUM($E$2:E10)
A11: Forsaljning 9 | B11: 29729 | C11: 32810 | D11: -9537 | E11: =SUM(B11:D11) | F11: =E11*0.25 | G11: =E11-F11 | H11: =IF(B11>0,G11/B11,0) | I11: =SUM($E$2:E11)
A12: IT 10 | B12: 2298 | C12: -1790 | D12: -9811 | E12: =SUM(B12:D12) | F12: =E12*0.25 | G12: =E12-F12 | H12: =IF(B12>0,G12/B12,0) | I12: =SUM($E$2:E12)
A13: Kontor 11 | B13: 30036 | C13: 2059 | D13: -13302 | E13: =SUM(B13:D13) | F13: =E13*0.25 | G13: =E13-F13 | H13: =IF(B13>0,G13/B13,0) | I13: =SUM($E$2:E13)
... A30001: Lager 29999 | B30001: 5482 | C30001: -16122 | D30001: 11482 | E30001: =SUM(B30001:D30001) | F30001: =E30001*0.25 | G30001: =E30001-F30001 | H30001: =IF(B30001>0,G30001/B30001,0) | I30001: =SUM($E$2:E30001)
B30021: =B30020+1
B30023: =B30022+1
B30025: =B30024+1
B30027: =B30026+1
B30029: =B30028+1
B30031: =B30030+1
B30033: =B30032+1
B30035: =B30034+1
B30037: =B30036+1
B30039: =B30038+1
B30041: =B30040+1
B30043: =B30042+1
... B30319: =B30318+1
A30420: Saknad post
B30421: =B30420*1.25
B30422: =B30420+B30421
A30423: Saknad post
B30424: =B30423*1.25
B30425: =B30423+B30424
B30427: =B30426*1.25
B30428: =B30426+B30427
B30430: =B30429*1.25
B30431: =B30429+B30430
B30433: =B30432*1.25
B30434: =B30432+B30433
B30436: =B30435*1.25
...

Sheet Berakning
A1: Nyckeltal | B1: Varde | C1: Faktor
A2: KPI 0 | B2: 0.082 | C2: 1.313
A3: KPI 1 | B3: 0.765 | C3: 0.956
A4: KPI 2 | B4: 0.907 | C4: 1.092
A5: KPI 3 | B5: 0.626 | C5: 1.131
A6: KPI 4 | B6: 0.131 | C6: 0.867
A7: KPI 5 | B7: 0.39 | C7: 1.19
A8: KPI 6 | B8: 0.825 | C8: 1.391
A9: KPI 7 | B9: 0.831 | C9: 1.222
A10: KPI 8 | B10: 0.232 | C10: 1.022
A11: KPI 9 | B11: 0.085 | C11: 1.194
A12: KPI 10 | B12: 0.288 | C12: 1.14
A13: KPI 11 | B13: 0.048 | C13: 1.031
... A61: KPI 59 | B61: 0.138 | C61: 1.167

Sheet Mall
A1: Skyddad mall | B1: Andra inte

Sheet Granska dessa
A1: GRANSKA DESSA — Excel Repair Pipeline
A2: Problem som hittats men inte ändrats — siffrorna här kan vara missvisande. Kolumnen Antal visar hur många liknande ställen som hittades.
A4: Typ | B4: Blad | C4: Plats | D4: Detalj | E4: Antal
A5: Summering missar data utanför området | B5: Sammanfattning | C5: B91 | D5: område B2:B90, data i: B92 | E5: 3
A6: Summering missar data utanför området | B6: Data | C6: G30920 | D6: område G30910:G30919, data i: G30921 | E6: 1
A7: Formel läser dolt blad | B7: Sammanfattning | C7: B2 | D7: läser 'Berakning' | E7: 1
A8: Formel läser dolt blad | B8: Sammanfattning | C8: C2 | D8: läser 'Berakning' | E8: 1
A9: Formel läser dolt blad | B9: Sammanfattning | C9: D2 | D9: läser 'Berakning' | E9: 1
A10: Formel läser dolt blad | B10: Sammanfattning | C10: B3 | D10: läser 'Berakning' | E10: 1
A11: Formel läser dolt blad | B11: Sammanfattning | C11: C3 | D11: läser 'Berakning' | E11: 1
A12: Formel läser dolt blad | B12: Sammanfattning | C12: D3 | D12: läser 'Berakning' | E12: 1
A13: Formel läser dolt blad | B13: Sammanfattning | C13: B4 | D13: läser 'Berakning' | E13: 1
A14: Formel läser dolt blad | B14: Sammanfattning | C14: C4 | D14: läser 'Berakning' | E14: 1
A15: Formel läser dolt blad | B15: Sammanfattning | C15: D4 | D15: läser 'Berakning' | E15: 1
... A27: Formel läser extern fil | B27: Sammanfattning | C27: B50, C50, B51, C51, B52 | D27: 40 celler → Gamla_2023.xlsx | E27: 40
A28: Nytt felvärde efter reparation | B28: Sammanfattning | C28: E50 | E28: 1
A29: Nytt felvärde efter reparation | B29: Sammanfattning | C29: E51 | E29: 1
A30: Nytt felvärde efter reparation | B30: Sammanfattning | C30: E52 | E30: 1
A31: Nytt felvärde efter reparation | B31: Sammanfattning | C31: E53 | E31: 1
A32: Nytt felvärde efter reparation | B32: Sammanfattning | C32: E54 | E32: 1
A33: Nytt felvärde efter reparation | B33: Sammanfattning | C33: E55 | E33: 1
A34: Nytt felvärde efter reparation | B34: Sammanfattning | C34: E56 | E34: 1
A35: Nytt felvärde efter reparation | B35: Sammanfattning | C35: E57 | E35: 1
A36: Nytt felvärde efter reparation | B36: Sammanfattning | C36: E58 | E36: 1
A37: Nytt felvärde efter reparation | B37: Sammanfattning | C37: E59 | E37: 1
A38: Nytt felvärde efter reparation | B38: Sammanfattning | C38: E60 | E38: 1
A39: Nytt felvärde efter reparation | B39: Sammanfattning | C39: E61 | E39: 1
... A47: Nytt felvärde efter reparation | B47: Sammanfattning | C47: E69 | E47: 1
A48: Dolt blad | B48: Berakning | C48: Berakning | D48: bladet är hidden — innehållet finns kvar | E48: 1

Sheet Ändringslogg
A1: ÄNDRINGSLOGG — Excel Repair Pipeline
A2: Ändringar av typen 'gissning'/'okänd' listas per cell nedan — de bör kontrolleras av en människa. Mekaniska ändringar ('säkra', t.ex. text→tal) summeras per blad längst ner.
A4: ÄNDRINGAR ATT GRANSKA
A5: Blad | B5: Cell | C5: Före | D5: Efter | E5: Åtgärd | F5: Typ
A6: Sammanfattning | B6: E50 | D6: =SUM(B50:D50) | E6: formel återskapad ur kolumnmönster | F6: gissning
A7: Sammanfattning | B7: E51 | D7: =SUM(B51:D51) | E7: formel återskapad ur kolumnmönster | F7: gissning
A8: Sammanfattning | B8: E52 | D8: =SUM(B52:D52) | E8: formel återskapad ur kolumnmönster | F8: gissning
A9: Sammanfattning | B9: E53 | D9: =SUM(B53:D53) | E9: formel återskapad ur kolumnmönster | F9: gissning
A10: Sammanfattning | B10: E54 | D10: =SUM(B54:D54) | E10: formel återskapad ur kolumnmönster | F10: gissning
A11: Sammanfattning | B11: E55 | D11: =SUM(B55:D55) | E11: formel återskapad ur kolumnmönster | F11: gissning
A12: Sammanfattning | B12: E56 | D12: =SUM(B56:D56) | E12: formel återskapad ur kolumnmönster | F12: gissning
A13: Sammanfattning | B13: E57 | D13: =SUM(B57:D57) | E13: formel återskapad ur kolumnmönster | F13: gissning
A14: Sammanfattning | B14: E58 | D14: =SUM(B58:D58) | E14: formel återskapad ur kolumnmönster | F14: gissning
A15: Sammanfattning | B15: E59 | D15: =SUM(B59:D59) | E15: formel återskapad ur kolumnmönster | F15: gissning
A16: Sammanfattning | B16: E60 | D16: =SUM(B60:D60) | E16: formel återskapad ur kolumnmönster | F16: gissning
A17: Sammanfattning | B17: E61 | D17: =SUM(B61:D61) | E17: formel återskapad ur kolumnmönster | F17: gissning
... A25: Sammanfattning | B25: E69 | D25: =SUM(B69:D69) | E25: formel återskapad ur kolumnmönster | F25: gissning
A26: Sammanfattning | B26: B70 | C26: =SUM(Data!B70:D70)+#REF! | D26: =SUM(Data!B70:D70) | E26: formel ändrad | F26: gissning
A27: Sammanfattning | B27: E70 | D27: =SUM(B70:D70) | E27: formel återskapad ur kolumnmönster | F27: gissning
A28: Sammanfattning | B28: B71 | C28: =SUM(Data!B71:D71)+#REF! | D28: =SUM(Data!B71:D71) | E28: formel ändrad | F28: gissning
A29: Sammanfattning | B29: E71 | D29: =SUM(B71:D71) | E29: formel återskapad ur kolumnmönster | F29: gissning
A30: Sammanfattning | B30: B72 | C30: =SUM(Data!B72:D72)+#REF! | D30: =SUM(Data!B72:D72) | E30: formel ändrad | F30: gissning
A31: Sammanfattning | B31: E72 | D31: =SUM(B72:D72) | E31: formel återskapad ur kolumnmönster | F31: gissning
A32: Sammanfattning | B32: B73 | C32: =SUM(Data!B73:D73)+#REF! | D32: =SUM(Data!B73:D73) | E32: formel ändrad | F32: gissning
A33: Sammanfattning | B33: E73 | D33: =SUM(B73:D73) | E33: formel återskapad ur kolumnmönster | F33: gissning
A34: Sammanfattning | B34: B74 | C34: =SUM(Data!B74:D74)+#REF! | D34: =SUM(Data!B74:D74) | E34: formel ändrad | F34: gissning
A35: Sammanfattning | B35: E74 | D35: =SUM(B74:D74) | E35: formel återskapad ur kolumnmönster | F35: gissning
A36: Sammanfattning | B36: B75 | C36: =SUM(Data!B75:D75)+#REF! | D36: =SUM(Data!B75:D75) | E36: formel ändrad | F36: gissning
A37: Sammanfattning | B37: E75 | D37: =SUM(B75:D75) | E37: formel återskapad ur kolumnmönster | F37: gissning
A38: Sammanfattning | B38: B76 | C38: =SUM(Data!B76:D76)+#REF! | D38: =SUM(Data!B76:D76) | E38: formel ändrad | F38: gissning
A39: Sammanfattning | B39: E76 | D39: =SUM(B76:D76) | E39: formel återskapad ur kolumnmönster | F39: gissning
A40: Sammanfattning | B40: B77 | C40: =SUM(Data!B77:D77)+#REF! | D40: =SUM(Data!B77:D77) | E40: formel ändrad | F40: gissning
A41: Sammanfattning | B41: E77 | D41: =SUM(B77:D77) | E41: formel återskapad ur kolumnmönster | F41: gissning
A42: Sammanfattning | B42: B78 | C42: =SUM(Data!B78:D78)+#REF! | D42: =SUM(Data!B78:D78) | E42: formel ändrad | F42: gissning
A43: Sammanfattning | B43: E78 | D43: =SUM(B78:D78) | E43: formel återskapad ur kolumnmönster | F43: gissning
A44: Sammanfattning | B44: B79 | C44: =SUM(Data!B79:D79)+#REF! | D44: =SUM(Data!B79:D79) | E44: formel ändrad | F44: gissning
A45: Sammanfattning | B45: E79 | D45: =SUM(B79:D79) | E45: formel återskapad ur kolumnmönster | F45: gissning
A46: Sammanfattning | B46: B80 | C46: =SUM(Data!B80:D80)+#REF! | D46: =SUM(Data!B80:D80) | E46: formel ändrad | F46: gissning
A47: Sammanfattning | B47: E80 | D47: =SUM(B80:D80) | E47: formel återskapad ur kolumnmönster | F47: gissning
A48: Sammanfattning | B48: B81 | C48: =SUM(Data!B81:D81)+#REF! | D48: =SUM(Data!B81:D81) | E48: formel ändrad | F48: gissning
...
